Traceback (most recent call last):
  File "/Users/stepanzh/Venv/jupyterbook/lib/python3.8/site-packages/jupyter_cache/executors/utils.py", line 51, in single_nb_execution
    executenb(
  File "/Users/stepanzh/Venv/jupyterbook/lib/python3.8/site-packages/nbclient/client.py", line 1117, in execute
    return NotebookClient(nb=nb, resources=resources, km=km, **kwargs).execute()
  File "/Users/stepanzh/Venv/jupyterbook/lib/python3.8/site-packages/nbclient/util.py", line 78, in wrapped
    return just_run(coro(*args, **kwargs))
  File "/Users/stepanzh/Venv/jupyterbook/lib/python3.8/site-packages/nbclient/util.py", line 57, in just_run
    return loop.run_until_complete(coro)
  File "/usr/local/opt/python@3.8/Frameworks/Python.framework/Versions/3.8/lib/python3.8/asyncio/base_events.py", line 616, in run_until_complete
    return future.result()
  File "/Users/stepanzh/Venv/jupyterbook/lib/python3.8/site-packages/nbclient/client.py", line 558, in async_execute
    await self.async_execute_cell(
  File "/Users/stepanzh/Venv/jupyterbook/lib/python3.8/site-packages/nbclient/client.py", line 862, in async_execute_cell
    self._check_raise_for_error(cell, exec_reply)
  File "/Users/stepanzh/Venv/jupyterbook/lib/python3.8/site-packages/nbclient/client.py", line 765, in _check_raise_for_error
    raise CellExecutionError.from_cell_and_msg(cell, exec_reply_content)
nbclient.exceptions.CellExecutionError: An error occurred while executing the following cell:
------------------
fixedpoint(g, -0.1; maxiter=100)
------------------

Число итераций превышено.

Stacktrace:
 [1] error(s::String)
   @ Base ./error.jl:33
 [2] fixedpoint(g::var"#29#30", x₁::Float64; xtol::Float64, maxiter::Int64)
   @ Main ~/JIHT/computational_thermodynamics/book/src.jl:272
 [3] top-level scope
   @ In[3]:1
 [4] eval
   @ ./boot.jl:360 [inlined]
 [5] include_string(mapexpr::typeof(REPL.softscope), mod::Module, code::String, filename::String)
   @ Base ./loading.jl:1116
LoadError: Число итераций превышено.

